2022-03-04 12:12:28,555 INFO    MainThread:670606 [wandb_setup.py:_flush():71] setting env: {}
2022-03-04 12:12:28,555 INFO    MainThread:670606 [wandb_setup.py:_flush():71] setting login settings: {}
2022-03-04 12:12:28,555 INFO    MainThread:670606 [wandb_setup.py:_flush():71] setting login settings: {}
2022-03-04 12:12:28,555 INFO    MainThread:670606 [wandb_init.py:_log_setup():371] Logging user logs to /home/junshick/Workspace/pose_estimation/custom_pose/wandb/run-20220304_121228-1wooyaax/logs/debug.log
2022-03-04 12:12:28,555 INFO    MainThread:670606 [wandb_init.py:_log_setup():372] Logging internal logs to /home/junshick/Workspace/pose_estimation/custom_pose/wandb/run-20220304_121228-1wooyaax/logs/debug-internal.log
2022-03-04 12:12:28,555 INFO    MainThread:670606 [wandb_init.py:init():404] calling init triggers
2022-03-04 12:12:28,555 INFO    MainThread:670606 [wandb_init.py:init():411] wandb.init called with sweep_config: {}
config: {}
2022-03-04 12:12:28,555 INFO    MainThread:670606 [wandb_init.py:init():460] starting backend
2022-03-04 12:12:28,555 INFO    MainThread:670606 [backend.py:_multiprocessing_setup():101] multiprocessing start_methods=fork,spawn,forkserver, using: spawn
2022-03-04 12:12:28,562 INFO    MainThread:670606 [backend.py:ensure_launched():216] starting backend process...
2022-03-04 12:12:28,565 INFO    MainThread:670606 [backend.py:ensure_launched():222] started backend process with pid: 670615
2022-03-04 12:12:28,566 INFO    MainThread:670606 [wandb_init.py:init():469] backend started and connected
2022-03-04 12:12:28,568 INFO    MainThread:670606 [wandb_init.py:init():533] updated telemetry
2022-03-04 12:12:28,580 INFO    MainThread:670606 [wandb_init.py:init():563] communicating current version
2022-03-04 12:12:29,035 INFO    MainThread:670606 [wandb_init.py:init():568] got version response upgrade_message: "wandb version 0.12.11 is available!  To upgrade, please run:\n $ pip install wandb --upgrade"

2022-03-04 12:12:29,035 INFO    MainThread:670606 [wandb_init.py:init():578] communicating run to backend with 30 second timeout
2022-03-04 12:12:29,264 INFO    MainThread:670606 [wandb_init.py:init():606] starting run threads in backend
2022-03-04 12:12:31,898 INFO    MainThread:670606 [wandb_run.py:_console_start():1810] atexit reg
2022-03-04 12:12:31,899 INFO    MainThread:670606 [wandb_run.py:_redirect():1684] redirect: SettingsConsole.REDIRECT
2022-03-04 12:12:31,899 INFO    MainThread:670606 [wandb_run.py:_redirect():1689] Redirecting console.
2022-03-04 12:12:31,901 INFO    MainThread:670606 [wandb_run.py:_redirect():1745] Redirects installed.
2022-03-04 12:12:31,901 INFO    MainThread:670606 [wandb_init.py:init():633] run started, returning control to user process
2022-03-04 12:12:45,844 INFO    MainThread:670606 [wandb_run.py:_atexit_cleanup():1780] got exitcode: 1
2022-03-04 12:12:45,844 INFO    MainThread:670606 [wandb_run.py:_restore():1752] restore
2022-03-04 12:12:48,121 INFO    MainThread:670606 [wandb_run.py:_restore():1752] restore
2022-03-04 12:12:50,526 ERROR   MainThread:670606 [wandb_run.py:_atexit_cleanup():1798] Problem finishing run
Traceback (most recent call last):
  File "/home/junshick/anaconda3/lib/python3.7/site-packages/wandb/sdk/wandb_run.py", line 1788, in _atexit_cleanup
    self._on_finish()
  File "/home/junshick/anaconda3/lib/python3.7/site-packages/wandb/sdk/wandb_run.py", line 1936, in _on_finish
    self._console_stop()  # TODO: there's a race here with jupyter console logging
  File "/home/junshick/anaconda3/lib/python3.7/site-packages/wandb/sdk/wandb_run.py", line 1828, in _console_stop
    self._restore()
  File "/home/junshick/anaconda3/lib/python3.7/site-packages/wandb/sdk/wandb_run.py", line 1758, in _restore
    self._err_redir.uninstall()
  File "/home/junshick/anaconda3/lib/python3.7/site-packages/wandb/sdk/lib/redirect.py", line 747, in uninstall
    self._emulator_write_thread.join(timeout=5)
  File "/home/junshick/anaconda3/lib/python3.7/threading.py", line 1048, in join
    self._wait_for_tstate_lock(timeout=max(timeout, 0))
  File "/home/junshick/anaconda3/lib/python3.7/threading.py", line 1060, in _wait_for_tstate_lock
    elif lock.acquire(block, timeout):
  File "/home/junshick/anaconda3/lib/python3.7/site-packages/wandb/sdk/lib/redirect.py", line 649, in handler
    self.handle_window_size_change()
  File "/home/junshick/anaconda3/lib/python3.7/site-packages/wandb/sdk/lib/redirect.py", line 680, in handle_window_size_change
    fcntl.ioctl(fd, termios.TIOCSWINSZ, win_size)
OSError: [Errno 9] Bad file descriptor
